<mujoco model="arm_6dof">
  <option timestep="0.002" gravity="0 0 -9.81"/>
  <default>
    <joint damping="0.5" armature="0.01"/>
    <geom contype="1" conaffinity="1" rgba="0.6 0.6 0.8 1"/>
    <motor ctrllimited="true" ctrlrange="-150 150"/>
  </default>
  <worldbody>
    <body name="base" pos="0 0 0">
      <geom name="base_geom" type="cylinder" size="0.08 0.02" rgba="0.4 0.4 0.5 1"/>
      <body name="link1" pos="0 0 0.05">
        <joint name="joint1" type="hinge" axis="0 0 1" range="-3.14 3.14"/>
        <geom name="link1_geom" type="cylinder" size="0.04 0.06" pos="0 0 0.06" rgba="0.7 0.3 0.3 1"/>
        <body name="link2" pos="0 0 0.12">
          <joint name="joint2" type="hinge" axis="0 1 0" range="-3.14 3.14"/>
          <geom name="link2_geom" type="cylinder" size="0.035 0.05" pos="0 0 0.05" rgba="0.3 0.7 0.3 1"/>
          <body name="link3" pos="0 0 0.1">
            <joint name="joint3" type="hinge" axis="0 1 0" range="-3.14 3.14"/>
            <geom name="link3_geom" type="cylinder" size="0.03 0.05" pos="0 0 0.05" rgba="0.3 0.3 0.7 1"/>
            <body name="link4" pos="0 0 0.1">
              <joint name="joint4" type="hinge" axis="1 0 0" range="-3.14 3.14"/>
              <geom name="link4_geom" type="cylinder" size="0.025 0.04" pos="0 0 0.04" rgba="0.7 0.7 0.3 1"/>
              <body name="link5" pos="0 0 0.08">
                <joint name="joint5" type="hinge" axis="0 1 0" range="-3.14 3.14"/>
                <geom name="link5_geom" type="cylinder" size="0.02 0.03" pos="0 0 0.03" rgba="0.7 0.3 0.7 1"/>
                <body name="link6" pos="0 0 0.06">
                  <joint name="joint6" type="hinge" axis="1 0 0" range="-3.14 3.14"/>
                  <geom name="link6_geom" type="capsule" fromto="0 0 0 0 0 0.04" size="0.02" rgba="0.5 0.5 0.5 1"/>
                  <site name="ee_site" pos="0 0 0.04" size="0.01"/>
                </body>
              </body>
            </body>
          </body>
        </body>
      </body>
    </body>
  </worldbody>
  <actuator>
    <motor name="actuator1" joint="joint1"/>
    <motor name="actuator2" joint="joint2"/>
    <motor name="actuator3" joint="joint3"/>
    <motor name="actuator4" joint="joint4"/>
    <motor name="actuator5" joint="joint5"/>
    <motor name="actuator6" joint="joint6"/>
  </actuator>
</mujoco>
